/GPUFS/nsccgz_ywang_zfd/anaconda3/envs/lora/bin/python: can't open file '/GPUFS/nsccgz_ywang_zfd/glh/code/llama-recipes-09-11/inference/llama_finetuning.py': [Errno 2] No such file or directory
/GPUFS/nsccgz_ywang_zfd/anaconda3/envs/lora/bin/python: can't open file '/GPUFS/nsccgz_ywang_zfd/glh/code/llama-recipes-09-11/inference/llama_finetuning.py': [Errno 2] No such file or directory
ERROR:torch.distributed.elastic.multiprocessing.api:failed (exitcode: 2) local_rank: 0 (pid: 45701) of binary: /GPUFS/nsccgz_ywang_zfd/anaconda3/envs/lora/bin/python
Traceback (most recent call last):
  File "/GPUFS/nsccgz_ywang_zfd/anaconda3/envs/lora/bin/torchrun", line 8, in <module>
    sys.exit(main())
  File "/GPUFS/nsccgz_ywang_zfd/anaconda3/envs/lora/lib/python3.10/site-packages/torch/distributed/elastic/multiprocessing/errors/__init__.py", line 346, in wrapper
    return f(*args, **kwargs)
  File "/GPUFS/nsccgz_ywang_zfd/anaconda3/envs/lora/lib/python3.10/site-packages/torch/distributed/run.py", line 794, in main
    run(args)
  File "/GPUFS/nsccgz_ywang_zfd/anaconda3/envs/lora/lib/python3.10/site-packages/torch/distributed/run.py", line 785, in run
    elastic_launch(
  File "/GPUFS/nsccgz_ywang_zfd/anaconda3/envs/lora/lib/python3.10/site-packages/torch/distributed/launcher/api.py", line 134, in __call__
    return launch_agent(self._config, self._entrypoint, list(args))
  File "/GPUFS/nsccgz_ywang_zfd/anaconda3/envs/lora/lib/python3.10/site-packages/torch/distributed/launcher/api.py", line 250, in launch_agent
    raise ChildFailedError(
torch.distributed.elastic.multiprocessing.errors.ChildFailedError: 
============================================================
llama_finetuning.py FAILED
------------------------------------------------------------
Failures:
[1]:
  time      : 2023-09-13_13:53:20
  host      : cwq-77cdb645b9-xgdxs
  rank      : 1 (local_rank: 1)
  exitcode  : 2 (pid: 45702)
  error_file: <N/A>
  traceback : To enable traceback see: https://pytorch.org/docs/stable/elastic/errors.html
------------------------------------------------------------
Root Cause (first observed failure):
[0]:
  time      : 2023-09-13_13:53:20
  host      : cwq-77cdb645b9-xgdxs
  rank      : 0 (local_rank: 0)
  exitcode  : 2 (pid: 45701)
  error_file: <N/A>
  traceback : To enable traceback see: https://pytorch.org/docs/stable/elastic/errors.html
============================================================
